Workbook
Name budget: 'Budget Dashboard'!$L1
Name budget_range: 'Budget Dashboard'!$Q1
Name budget_rank: 'Budget Dashboard'!$R1
Name cc_budget: Calculations!$K1
Name cc_delta: Calculations!$L1
Name cc_in_focus: Calculations!$G1
Name cc_month_number: Calculations!$F1
Name cc_show_remaining_budget: Calculations!$I1
Name cc_show_type: Calculations!$H1
Name cc_tracked: Calculations!$J1
Name cc_type: Calculations!$E1
Name comb_rank: 'Budget Dashboard'!$S1
Name comb_rank_norm: 'Budget Dashboard'!$U1
Name comb_rank_norm_run_range: 'Budget Dashboard'!$V1
Name comb_rank_range: 'Budget Dashboard'!$T1
Name comb_rank_unique: 'Budget Dashboard'!$W1
Name current_date: TODAY()
Name expenses_header_row: ROW(Expenses[[#Headers],[Expenses]])
Name expenses_max_row: MAX(ROW(Expenses[]))
Name expenses_min_row: MIN(ROW(Expenses[]))
Name expenses_total_row: ROW('Budget Planning'!$C$102)
Name header_row_id: 'Budget Dashboard'!$D1
Name income_header_row: ROW(Income[[#Headers],[Income]])
Name income_max_row: MAX(ROW(Income[]))
Name income_min_row: MIN(ROW(Income[]))
Name income_total_row: ROW('Budget Planning'!$C$20)
Name is_cat: 'Budget Dashboard'!$F1
Name is_empty: 'Budget Dashboard'!$H1
Name is_header: 'Budget Dashboard'!$E1
Name is_total: 'Budget Dashboard'!$G1
Name item: 'Budget Dashboard'!$J1
Name out_budget: 'Budget Dashboard'!$AA1
Name out_percentage_completed: 'Budget Dashboard'!$AB1
Name out_tracked: 'Budget Dashboard'!$Z1
Name row_id: 'Budget Dashboard'!$C1
Name savings_header_row: ROW(Savings[[#Headers],[Savings]])
Name savings_max_row: MAX(ROW(Savings[]))
Name savings_min_row: MIN(ROW(Savings[]))
Name savings_rate_calculation_type: Settings!$E$22
Name savings_total_row: ROW('Budget Planning'!$C$115)
Name selected_period: Calculations!$E$20
Name selected_period_display: Calculations!$E$21
Name selected_year: Calculations!$E$19
Name shift_late_income_starting_day: Settings!$E$18
Name shift_late_income_status: Settings!$E$16
Name sort_max_row: 'Budget Dashboard'!$N1
Name sort_min_row: 'Budget Dashboard'!$M1
Name starting_year: Settings!$E$8
Name tracked: 'Budget Dashboard'!$K1
Name tracked_range: 'Budget Dashboard'!$O1
Name tracked_rank: 'Budget Dashboard'!$P1
Name type: 'Budget Dashboard'!$I1

Sheet Info
B2: Template Information
C6: File Information | H6: Quick Start Help
D8: File Name: | E8: Ultimate Excel Personal Budget | I8: Template Structure: | J8: This template has two relevant worksheets: - Settings: Set the most important parameters for your personal budget - Budget Planning: Define your custom Income, Expense, and Savings categories and create a multi-period budget plan - Budget Tracking: Track your actual money flows and assign them to your defined custom categories - Budget Dashboard: Monitor and analyse your budget performance for the current and historic months and years You should always start by (1) setting the starting year in the Settings sheet, then (2) defining your custom categories and (3) setting up a budget plan in the Budget Planning sheet.
D10: File Author: | E10: The Office Lab
D12: File License: | E12: With the purchase of this template you have one license for your personal use. This license covers all members of your household. However, an unauthorized redistribution of this file or any sort of derivate of this file for commercial gain is not permitted.
I13: Budget Planning: | J13: Adding New Categories To add a new categorry in any of the three sections (Income, Expenses, Savings), unhide the empty placeholder rows in column C and overwrite the placeholders right below the respective section table. As soon as a category is part of the respective section table in column C, it will be considered and displayed in all sheets of the workbook. Creating a Zero-Based Budget Plan When you plan your budget values for all categories in a month, the goal is to allocate every disposable dollar from income to either categories or savings, so that in the end Income - (Expenses + Savings) = 0 for each individual month. In the upper section (row 6 & 7) you will always see how much of your planned income is still left to be allocated for each month.
D14: Documentation & Help: | E14: excelfind.com/documentation/ultimate-excel-personal-budget
D16: Disclaimer: | E16: No liability is taken for any damage that might arise related to the use of this template in a business or personal context.
C19: Other Templates
E21: We invite you to take a look at our most popular Excel template for project management: The Ultimate Excel Gantt Chart. It's the most advanced Excel Gantt Chart template on the market that allows you to create a complex project schedule with dynamic task dependencies, automatic coloring, actual vs base plan comparison, and many more features. | I21: Budget Tracking: | J21: Tracking Money Flows You can add a new record to the Tracking table by entering a date, then selecting a type (income, expenses, or savings), choosing one of the respective categories, entering the amount (as an absolute number for all types) and the details of the transaction. Your records do not necessarily have to be entered or sorted in chronological order for the template to function correctly. That means, you can always enter "older" transactions at the bottom of the table and bring them to the chronologically correct position simply by sorting the Date column.
I27: More information: | J27: For more detailed information on all features and how they were built, take a look at the 'Documentation & Help' page (link on the left).

Sheet Settings
B2: Settings
C6: General
D8: Starting Year: | E8: 2024 | G8: Set the starting year (yyyy) once at the beginning and do not change it again.
C12: Budget Tracking & Dashboard
D14: Late Monthly Income
D16: Shift late income: | E16: Inactive | G16: Activate this option to treat late income received on or after a certain day of the month as income for the next month. This is especially recommended in case you receive your monthly paycheck towards the end of the month and prefer to consider this income as the disposable income for the next month.
D18: Starting on day x in month: | E18: 20
D20: KPI Calculation in Dashboard
D22: Savings Rate as % of Income: | E22: % allocated to Savings | G22: Choose how you want the savings rate (SR) to be calculated in the dashboard KPI tiles: 1) Active Option (% allocated to Savings): SR = Savings / Income 2) Passive Option (% not allocated to Expenses): SR = (Income - Expenses) / Income

Sheet Budget Planning
B2: Budget Planning
C5: Define starting year in Settings ➜ | E5: =starting_year -> 2024 | S5: =E5+1 -> 2025 | AG5: =S5+1 -> 2026 | AU5: =AG5+1 -> 2027 | BI5: =AU5+1 -> 2028 | BW5: =BI5+1 -> 2029 | CK5: =BW5+1 -> 2030 | CY5: =CK5+1 -> 2031 | DM5: =CY5+1 -> 2032 | EA5: =DM5+1 -> 2033
E6: =IF(E7=0, "Jan ✓", "Jan") -> Jan ✓ | F6: =IF(F7=0, "Feb ✓", "Feb") -> Feb ✓ | G6: =IF(G7=0, "Mar ✓", "Mar") -> Mar ✓ | H6: =IF(H7=0, "Apr ✓", "Apr") -> Apr ✓ | I6: =IF(I7=0, "May ✓", "May") -> May ✓ | J6: =IF(J7=0, "Jun ✓", "Jun") -> Jun | K6: =IF(K7=0, "Jul ✓", "Jul") -> Jul | L6: =IF(L7=0, "Aug ✓", "Aug") -> Aug | M6: =IF(M7=0, "Sep ✓", "Sep") -> Sep | N6: =IF(N7=0, "Oct ✓", "Oct") -> Oct | O6: =IF(O7=0, "Nov ✓", "Nov") -> Nov | P6: =IF(P7=0, "Dec ✓", "Dec") -> Dec | Q6: =IF(Q7=0, "Total ✓", "Total") -> Total | S6: =IF(S7=0, "Jan ✓", "Jan") -> Jan ✓ | T6: =IF(T7=0, "Feb ✓", "Feb") -> Feb ✓ | U6: =IF(U7=0, "Mar ✓", "Mar") -> Mar ✓ | V6: =IF(V7=0, "Apr ✓", "Apr") -> Apr ✓ | W6: =IF(W7=0, "May ✓", "May") -> May ✓ | X6: =IF(X7=0, "Jun ✓", "Jun") -> Jun ✓ | Y6: =IF(Y7=0, "Jul ✓", "Jul") -> Jul ✓ | Z6: =IF(Z7=0, "Aug ✓", "Aug") -> Aug ✓ | AA6: =IF(AA7=0, "Sep ✓", "Sep") -> Sep ✓ | AB6: =IF(AB7=0, "Oct ✓", "Oct") -> Oct ✓ | AC6: =IF(AC7=0, "Nov ✓", "Nov") -> Nov ✓ | AD6: =IF(AD7=0, "Dec ✓", "Dec") -> Dec ✓ | AE6: =IF(AE7=0, "Total ✓", "Total") -> Total ✓ | AG6: =IF(AG7=0, "Jan ✓", "Jan") -> Jan ✓ | AH6: =IF(AH7=0, "Feb ✓", "Feb") -> Feb | AI6: =IF(AI7=0, "Mar ✓", "Mar") -> Mar | AJ6: =IF(AJ7=0, "Apr ✓", "Apr") -> Apr | AK6: =IF(AK7=0, "May ✓", "May") -> May | AL6: =IF(AL7=0, "Jun ✓", "Jun") -> Jun | AM6: =IF(AM7=0, "Jul ✓", "Jul") -> Jul | AN6: =IF(AN7=0, "Aug ✓", "Aug") -> Aug | AO6: =IF(AO7=0, "Sep ✓", "Sep") -> Sep | AP6: =IF(AP7=0, "Oct ✓", "Oct") -> Oct | AQ6: =IF(AQ7=0, "Nov ✓", "Nov") -> Nov | AR6: =IF(AR7=0, "Dec ✓", "Dec") -> Dec | AS6: =IF(AS7=0, "Total ✓", "Total") -> Total | AU6: =IF(AU7=0, "Jan ✓", "Jan") -> Jan ✓ | AV6: =IF(AV7=0, "Feb ✓", "Feb") -> Feb ✓ | AW6: =IF(AW7=0, "Mar ✓", "Mar") -> Mar ✓ | AX6: =IF(AX7=0, "Apr ✓", "Apr") -> Apr ✓ | AY6: =IF(AY7=0, "May ✓", "May") -> May ✓ | AZ6: =IF(AZ7=0, "Jun ✓", "Jun") -> Jun ✓ | BA6: =IF(BA7=0, "Jul ✓", "Jul") -> Jul ✓ | BB6: =IF(BB7=0, "Aug ✓", "Aug") -> Aug ✓ | BC6: =IF(BC7=0, "Sep ✓", "Sep") -> Sep ✓ | BD6: =IF(BD7=0, "Oct ✓", "Oct") -> Oct ✓ | BE6: =IF(BE7=0, "Nov ✓", "Nov") -> Nov ✓ | BF6: =IF(BF7=0, "Dec ✓", "Dec") -> Dec ✓ | BG6: =IF(BG7=0, "Total ✓", "Total") -> Total ✓ | BI6: =IF(BI7=0, "Jan ✓", "Jan") -> Jan ✓ | BJ6: =IF(BJ7=0, "Feb ✓", "Feb") -> Feb ✓ | BK6: =IF(BK7=0, "Mar ✓", "Mar") -> Mar ✓ | BL6: =IF(BL7=0, "Apr ✓", "Apr") -> Apr ✓ | BM6: =IF(BM7=0, "May ✓", "May") -> May ✓ | BN6: =IF(BN7=0, "Jun ✓", "Jun") -> Jun ✓ | BO6: =IF(BO7=0, "Jul ✓", "Jul") -> Jul ✓ | BP6: =IF(BP7=0, "Aug ✓", "Aug") -> Aug ✓ | BQ6: =IF(BQ7=0, "Sep ✓", "Sep") -> Sep ✓ | BR6: =IF(BR7=0, "Oct ✓", "Oct") -> Oct ✓ | BS6: =IF(BS7=0, "Nov ✓", "Nov") -> Nov ✓ | BT6: =IF(BT7=0, "Dec ✓", "Dec") -> Dec ✓ | BU6: =IF(BU7=0, "Total ✓", "Total") -> Total ✓ | BW6: =IF(BW7=0, "Jan ✓", "Jan") -> Jan ✓ | BX6: =IF(BX7=0, "Feb ✓", "Feb") -> Feb ✓ | BY6: =IF(BY7=0, "Mar ✓", "Mar") -> Mar ✓ | BZ6: =IF(BZ7=0, "Apr ✓", "Apr") -> Apr ✓ | CA6: =IF(CA7=0, "May ✓", "May") -> May ✓ | CB6: =IF(CB7=0, "Jun ✓", "Jun") -> Jun ✓ | CC6: =IF(CC7=0, "Jul ✓", "Jul") -> Jul ✓ | CD6: =IF(CD7=0, "Aug ✓", "Aug") -> Aug ✓ | CE6: =IF(CE7=0, "Sep ✓", "Sep") -> Sep ✓ | CF6: =IF(CF7=0, "Oct ✓", "Oct") -> Oct ✓ | CG6: =IF(CG7=0, "Nov ✓", "Nov") -> Nov ✓ | CH6: =IF(CH7=0, "Dec ✓", "Dec") -> Dec ✓ | CI6: =IF(CI7=0, "Total ✓", "Total") -> Total ✓ | CK6: =IF(CK7=0, "Jan ✓", "Jan") -> Jan ✓ | CL6: =IF(CL7=0, "Feb ✓", "Feb") -> Feb ✓ | CM6: =IF(CM7=0, "Mar ✓", "Mar") -> Mar ✓ | CN6: =IF(CN7=0, "Apr ✓", "Apr") -> Apr ✓ | CO6: =IF(CO7=0, "May ✓", "May") -> May ✓ | CP6: =IF(CP7=0, "Jun ✓", "Jun") -> Jun ✓ | CQ6: =IF(CQ7=0, "Jul ✓", "Jul") -> Jul ✓ | CR6: =IF(CR7=0, "Aug ✓", "Aug") -> Aug ✓ | CS6: =IF(CS7=0, "Sep ✓", "Sep") -> Sep ✓ | CT6: =IF(CT7=0, "Oct ✓", "Oct") -> Oct ✓ | CU6: =IF(CU7=0, "Nov ✓", "Nov") -> Nov ✓ | CV6: =IF(CV7=0, "Dec ✓", "Dec") -> Dec ✓ | CW6: =IF(CW7=0, "Total ✓", "Total") -> Total ✓ | CY6: =IF(CY7=0, "Jan ✓", "Jan") -> Jan ✓ | CZ6: =IF(CZ7=0, "Feb ✓", "Feb") -> Feb ✓ | DA6: =IF(DA7=0, "Mar ✓", "Mar") -> Mar ✓ | DB6: =IF(DB7=0, "Apr ✓", "Apr") -> Apr ✓ | DC6: =IF(DC7=0, "May ✓", "May") -> May ✓ | DD6: =IF(DD7=0, "Jun ✓", "Jun") -> Jun ✓ | DE6: =IF(DE7=0, "Jul ✓", "Jul") -> Jul ✓ | DF6: =IF(DF7=0, "Aug ✓", "Aug") -> Aug ✓ | DG6: =IF(DG7=0, "Sep ✓", "Sep") -> Sep ✓ | DH6: =IF(DH7=0, "Oct ✓", "Oct") -> Oct ✓ | DI6: =IF(DI7=0, "Nov ✓", "Nov") -> Nov ✓ | DJ6: =IF(DJ7=0, "Dec ✓", "Dec") -> Dec ✓ | DK6: =IF(DK7=0, "Total ✓", "Total") -> Total ✓ | DM6: =IF(DM7=0, "Jan ✓", "Jan") -> Jan ✓ | DN6: =IF(DN7=0, "Feb ✓", "Feb") -> Feb ✓ | DO6: =IF(DO7=0, "Mar ✓", "Mar") -> Mar ✓ | DP6: =IF(DP7=0, "Apr ✓", "Apr") -> Apr ✓ | DQ6: =IF(DQ7=0, "May ✓", "May") -> May ✓ | DR6: =IF(DR7=0, "Jun ✓", "Jun") -> Jun ✓ | DS6: =IF(DS7=0, "Jul ✓", "Jul") -> Jul ✓ | DT6: =IF(DT7=0, "Aug ✓", "Aug") -> Aug ✓ | DU6: =IF(DU7=0, "Sep ✓", "Sep") -> Sep ✓ | DV6: =IF(DV7=0, "Oct ✓", "Oct") -> Oct ✓ | DW6: =IF(DW7=0, "Nov ✓", "Nov") -> Nov ✓ | DX6: =IF(DX7=0, "Dec ✓", "Dec") -> Dec ✓ | DY6: =IF(DY7=0, "Total ✓", "Total") -> Total ✓ | EA6: =IF(EA7=0, "Jan ✓", "Jan") -> Jan ✓ | EB6: =IF(EB7=0, "Feb ✓", "Feb") -> Feb ✓ | EC6: =IF(EC7=0, "Mar ✓", "Mar") -> Mar ✓ | ED6: =IF(ED7=0, "Apr ✓", "Apr") -> Apr ✓ | EE6: =IF(EE7=0, "May ✓", "May") -> May ✓ | EF6: =IF(EF7=0, "Jun ✓", "Jun") -> Jun ✓ | EG6: =IF(EG7=0, "Jul ✓", "Jul") -> Jul ✓ | EH6: =IF(EH7=0, "Aug ✓", "Aug") -> Aug ✓ | EI6: =IF(EI7=0, "Sep ✓", "Sep") -> Sep ✓ | EJ6: =IF(EJ7=0, "Oct ✓", "Oct") -> Oct ✓ | EK6: =IF(EK7=0, "Nov ✓", "Nov") -> Nov ✓ | EL6: =IF(EL7=0, "Dec ✓", "Dec") -> Dec ✓ | EM6: =IF(EM7=0, "Total ✓", "Total") -> Total ✓
C7: To be allocated: | E7: =E20-(E102+E115) -> 0 | F7: =F20-(F102+F115) -> 0 | G7: =G20-(G102+G115) -> 0 | H7: =H20-(H102+H115) -> 0 | I7: =I20-(I102+I115) -> 0 | J7: =J20-(J102+J115) -> -26 | K7: =K20-(K102+K115) -> -26 | L7: =L20-(L102+L115) -> -26 | ... Q7: =Q20-(Q102+Q115) -> 2318 | S7: =S20-(S102+S115) -> 0 | T7: =T20-(T102+T115) -> 0 | U7: =U20-(U102+U115) -> 0 | V7: =V20-(V102+V115) -> 0 | W7: =W20-(W102+W115) -> 0 | X7: =X20-(X102+X115) -> 0 | Y7: =Y20-(Y102+Y115) -> 0 | Z7: =Z20-(Z102+Z115) -> 0 | ... AE7: =AE20-(AE102+AE115) -> 0 | AG7: =AG20-(AG102+AG115) -> 0 | AH7: =AH20-(AH102+AH115) -> 7950 | AI7: =AI20-(AI102+AI115) -> 7950 | AJ7: =AJ20-(AJ102+AJ115) -> 7950 | AK7: =AK20-(AK102+AK115) -> 7950 | AL7: =AL20-(AL102+AL115) -> 7950 | AM7: =AM20-(AM102+AM115) -> 7950 | AN7: =AN20-(AN102+AN115) -> 7950 | ... AS7: =AS20-(AS102+AS115) -> 7780 | AU7: =AU20-(AU102+AU115) -> 0 | AV7: =AV20-(AV102+AV115) -> 0 | AW7: =AW20-(AW102+AW115) -> 0 | AX7: =AX20-(AX102+AX115) -> 0 | AY7: =AY20-(AY102+AY115) -> 0 | AZ7: =AZ20-(AZ102+AZ115) -> 0 | BA7: =BA20-(BA102+BA115) -> 0 | BB7: =BB20-(BB102+BB115) -> 0 | ... BG7: =BG20-(BG102+BG115) -> 0 | BI7: =BI20-(BI102+BI115) -> 0 | BJ7: =BJ20-(BJ102+BJ115) -> 0 | BK7: =BK20-(BK102+BK115) -> 0 | BL7: =BL20-(BL102+BL115) -> 0 | BM7: =BM20-(BM102+BM115) -> 0 | BN7: =BN20-(BN102+BN115) -> 0 | BO7: =BO20-(BO102+BO115) -> 0 | BP7: =BP20-(BP102+BP115) -> 0 | ... BU7: =BU20-(BU102+BU115) -> 0 | BW7: =BW20-(BW102+BW115) -> 0 | BX7: =BX20-(BX102+BX115) -> 0 | BY7: =BY20-(BY102+BY115) -> 0 | BZ7: =BZ20-(BZ102+BZ115) -> 0 | CA7: =CA20-(CA102+CA115) -> 0 | CB7: =CB20-(CB102+CB115) -> 0 | CC7: =CC20-(CC102+CC115) -> 0 | CD7: =CD20-(CD102+CD115) -> 0 | ... CI7: =CI20-(CI102+CI115) -> 0 | CK7: =CK20-(CK102+CK115) -> 0 | CL7: =CL20-(CL102+CL115) -> 0 | CM7: =CM20-(CM102+CM115) -> 0 | CN7: =CN20-(CN102+CN115) -> 0 | CO7: =CO20-(CO102+CO115) -> 0 | CP7: =CP20-(CP102+CP115) -> 0 | CQ7: =CQ20-(CQ102+CQ115) -> 0 | CR7: =CR20-(CR102+CR115) -> 0 | ... CW7: =CW20-(CW102+CW115) -> 0 | CY7: =CY20-(CY102+CY115) -> 0 | CZ7: =CZ20-(CZ102+CZ115) -> 0 | DA7: =DA20-(DA102+DA115) -> 0 | DB7: =DB20-(DB102+DB115) -> 0 | DC7: =DC20-(DC102+DC115) -> 0 | DD7: =DD20-(DD102+DD115) -> 0 | DE7: =DE20-(DE102+DE115) -> 0 | DF7: =DF20-(DF102+DF115) -> 0 | ... DK7: =DK20-(DK102+DK115) -> 0 | DM7: =DM20-(DM102+DM115) -> 0 | DN7: =DN20-(DN102+DN115) -> 0 | DO7: =DO20-(DO102+DO115) -> 0 | DP7: =DP20-(DP102+DP115) -> 0 | DQ7: =DQ20-(DQ102+DQ115) -> 0 | DR7: =DR20-(DR102+DR115) -> 0 | DS7: =DS20-(DS102+DS115) -> 0 | DT7: =DT20-(DT102+DT115) -> 0 | ... DY7: =DY20-(DY102+DY115) -> 0 | EA7: =EA20-(EA102+EA115) -> 0 | EB7: =EB20-(EB102+EB115) -> 0 | EC7: =EC20-(EC102+EC115) -> 0 | ED7: =ED20-(ED102+ED115) -> 0 | EE7: =EE20-(EE102+EE115) -> 0 | EF7: =EF20-(EF102+EF115) -> 0 | EG7: =EG20-(EG102+EG115) -> 0 | EH7: =EH20-(EH102+EH115) -> 0 | ... EM7: =EM20-(EM102+EM115) -> 0
C9: Income | E9: =DATE(E$5,1,1) -> 45292 | F9: =DATE(E$5,2,1) -> 45323 | G9: =DATE(E$5,3,1) -> 45352 | H9: =DATE(E$5,4,1) -> 45383 | I9: =DATE(E$5,5,1) -> 45413 | J9: =DATE(E$5,6,1) -> 45444 | K9: =DATE(E$5,7,1) -> 45474 | L9: =DATE(E$5,8,1) -> 45505 | M9: =DATE(E$5,9,1) -> 45536 | N9: =DATE(E$5,10,1) -> 45566 | O9: =DATE(E$5,11,1) -> 45597 | P9: =DATE(E$5,12,1) -> 45627 | Q9: =E$5 -> 2024 | S9: =DATE(S$5,1,1) -> 45658 | T9: =DATE(S$5,2,1) -> 45689 | U9: =DATE(S$5,3,1) -> 45717 | V9: =DATE(S$5,4,1) -> 45748 | W9: =DATE(S$5,5,1) -> 45778 | X9: =DATE(S$5,6,1) -> 45809 | Y9: =DATE(S$5,7,1) -> 45839 | Z9: =DATE(S$5,8,1) -> 45870 | AA9: =DATE(S$5,9,1) -> 45901 | AB9: =DATE(S$5,10,1) -> 45931 | AC9: =DATE(S$5,11,1) -> 45962 | AD9: =DATE(S$5,12,1) -> 45992 | AE9: =S$5 -> 2025 | AG9: =DATE(AG$5,1,1) -> 46023 | AH9: =DATE(AG$5,2,1) -> 46054 | AI9: =DATE(AG$5,3,1) -> 46082 | AJ9: =DATE(AG$5,4,1) -> 46113 | AK9: =DATE(AG$5,5,1) -> 46143 | AL9: =DATE(AG$5,6,1) -> 46174 | AM9: =DATE(AG$5,7,1) -> 46204 | AN9: =DATE(AG$5,8,1) -> 46235 | AO9: =DATE(AG$5,9,1) -> 46266 | AP9: =DATE(AG$5,10,1) -> 46296 | AQ9: =DATE(AG$5,11,1) -> 46327 | AR9: =DATE(AG$5,12,1) -> 46357 | AS9: =AG$5 -> 2026 | AU9: =DATE(AU$5,1,1) -> 46388 | AV9: =DATE(AU$5,2,1) -> 46419 | AW9: =DATE(AU$5,3,1) -> 46447 | AX9: =DATE(AU$5,4,1) -> 46478 | AY9: =DATE(AU$5,5,1) -> 46508 | AZ9: =DATE(AU$5,6,1) -> 46539 | BA9: =DATE(AU$5,7,1) -> 46569 | BB9: =DATE(AU$5,8,1) -> 46600 | BC9: =DATE(AU$5,9,1) -> 46631 | BD9: =DATE(AU$5,10,1) -> 46661 | BE9: =DATE(AU$5,11,1) -> 46692 | BF9: =DATE(AU$5,12,1) -> 46722 | BG9: =AU$5 -> 2027 | BI9: =DATE(BI$5,1,1) -> 46753 | BJ9: =DATE(BI$5,2,1) -> 46784 | BK9: =DATE(BI$5,3,1) -> 46813 | BL9: =DATE(BI$5,4,1) -> 46844 | BM9: =DATE(BI$5,5,1) -> 46874 | BN9: =DATE(BI$5,6,1) -> 46905 | BO9: =DATE(BI$5,7,1) -> 46935 | BP9: =DATE(BI$5,8,1) -> 46966 | BQ9: =DATE(BI$5,9,1) -> 46997 | BR9: =DATE(BI$5,10,1) -> 47027 | BS9: =DATE(BI$5,11,1) -> 47058 | BT9: =DATE(BI$5,12,1) -> 47088 | BU9: =BI$5 -> 2028 | BW9: =DATE(BW$5,1,1) -> 47119 | BX9: =DATE(BW$5,2,1) -> 47150 | BY9: =DATE(BW$5,3,1) -> 47178 | BZ9: =DATE(BW$5,4,1) -> 47209 | CA9: =DATE(BW$5,5,1) -> 47239 | CB9: =DATE(BW$5,6,1) -> 47270 | CC9: =DATE(BW$5,7,1) -> 47300 | CD9: =DATE(BW$5,8,1) -> 47331 | CE9: =DATE(BW$5,9,1) -> 47362 | CF9: =DATE(BW$5,10,1) -> 47392 | CG9: =DATE(BW$5,11,1) -> 47423 | CH9: =DATE(BW$5,12,1) -> 47453 | CI9: =BW$5 -> 2029 | CK9: =DATE(CK$5,1,1) -> 47484 | CL9: =DATE(CK$5,2,1) -> 47515 | CM9: =DATE(CK$5,3,1) -> 47543 | CN9: =DATE(CK$5,4,1) -> 47574 | CO9: =DATE(CK$5,5,1) -> 47604 | CP9: =DATE(CK$5,6,1) -> 47635 | CQ9: =DATE(CK$5,7,1) -> 47665 | CR9: =DATE(CK$5,8,1) -> 47696 | CS9: =DATE(CK$5,9,1) -> 47727 | CT9: =DATE(CK$5,10,1) -> 47757 | CU9: =DATE(CK$5,11,1) -> 47788 | CV9: =DATE(CK$5,12,1) -> 47818 | CW9: =CK$5 -> 2030 | CY9: =DATE(CY$5,1,1) -> 47849 | CZ9: =DATE(CY$5,2,1) -> 47880 | DA9: =DATE(CY$5,3,1) -> 47908 | DB9: =DATE(CY$5,4,1) -> 47939 | DC9: =DATE(CY$5,5,1) -> 47969 | DD9: =DATE(CY$5,6,1) -> 48000 | DE9: =DATE(CY$5,7,1) -> 48030 | DF9: =DATE(CY$5,8,1) -> 48061 | DG9: =DATE(CY$5,9,1) -> 48092 | DH9: =DATE(CY$5,10,1) -> 48122 | DI9: =DATE(CY$5,11,1) -> 48153 | DJ9: =DATE(CY$5,12,1) -> 48183 | DK9: =CY$5 -> 2031 | DM9: =DATE(DM$5,1,1) -> 48214 | DN9: =DATE(DM$5,2,1) -> 48245 | DO9: =DATE(DM$5,3,1) -> 48274 | DP9: =DATE(DM$5,4,1) -> 48305 | DQ9: =DATE(DM$5,5,1) -> 48335 | DR9: =DATE(DM$5,6,1) -> 48366 | DS9: =DATE(DM$5,7,1) -> 48396 | DT9: =DATE(DM$5,8,1) -> 48427 | DU9: =DATE(DM$5,9,1) -> 48458 | DV9: =DATE(DM$5,10,1) -> 48488 | DW9: =DATE(DM$5,11,1) -> 48519 | DX9: =DATE(DM$5,12,1) -> 48549 | DY9: =DM$5 -> 2032 | EA9: =DATE(EA$5,1,1) -> 48580 | EB9: =DATE(EA$5,2,1) -> 48611 | EC9: =DATE(EA$5,3,1) -> 48639 | ED9: =DATE(EA$5,4,1) -> 48670 | EE9: =DATE(EA$5,5,1) -> 48700 | EF9: =DATE(EA$5,6,1) -> 48731 | EG9: =DATE(EA$5,7,1) -> 48761 | EH9: =DATE(EA$5,8,1) -> 48792 | EI9: =DATE(EA$5,9,1) -> 48823 | EJ9: =DATE(EA$5,10,1) -> 48853 | EK9: =DATE(EA$5,11,1) -> 48884 | EL9: =DATE(EA$5,12,1) -> 48914 | EM9: =EA$5 -> 2033
C10: Salary Ivo | J10: 7300 | K10: 7300 | L10: 7300 | M10: 7300 | N10: 7300 | O10: 7300 | P10: 7300 | Q10: =SUM(F10:P10) -> 51100 | S10: 7500 | T10: 7500 | U10: 7500 | V10: 7500 | W10: 7500 | X10: 7500 | Y10: 7700 | Z10: 7700 | AA10: 7700 | AB10: 7700 | AC10: 7700 | AD10: 7700 | AE10: =SUM(S10:AD10) -> 91200 | AG10: 7700 | AH10: 7700 | AI10: 7700 | AJ10: 7700 | AK10: 7700 | AL10: 7700 | AM10: 7700 | AN10: 7700 | AO10: 7700 | AP10: 7700 | AQ10: 7700 | AR10: 7700 | AS10: 7700 | BG10: =SUM(AU10:BF10) -> 0 | BU10: =SUM(BI10:BT10) -> 0 | CI10: =SUM(BW10:CH10) -> 0 | CW10: =SUM(CK10:CV10) -> 0 | DK10: =SUM(CY10:DJ10) -> 0 | DY10: =SUM(DM10:DX10) -> 0 | EM10: =SUM(EA10:EL10) -> 0
C11: Salary Kalina | O11: 1000 | P11: 1000 | Q11: =SUM(E11:P11) -> 2000 | S11: 0 | T11: 0 | U11: 0 | V11: 0 | W11: 0 | X11: 0 | Y11: 0 | Z11: 0 | AA11: 0 | AB11: 0 | AC11: 0 | AD11: 0 | AE11: =SUM(S11:AD11) -> 0 | AG11: 0 | AH11: 0 | AI11: 0 | AJ11: 0 | AK11: 0 | AL11: 0 | AM11: 0 | AN11: 0 | AO11: 0 | AP11: 0 | AQ11: 0 | AR11: 0 | AS11: 0 | BG11: =SUM(AU11:BF11) -> 0 | BU11: =SUM(BI11:BT11) -> 0 | CI11: =SUM(BW11:CH11) -> 0 | CW11: =SUM(CK11:CV11) -> 0 | DK11: =SUM(CY11:DJ11) -> 0 | DY11: =SUM(DM11:DX11) -> 0 | EM11: =SUM(EA11:EL11) -> 0
C12: Rent | O12: 250 | P12: 250 | Q12: =SUM(E12:P12) -> 500 | S12: 250 | T12: 250 | U12: 250 | V12: 250 | W12: 250 | X12: 250 | Y12: 250 | Z12: 250 | AA12: 250 | AB12: 250 | AC12: 250 | AD12: 250 | AE12: =SUM(S12:AD12) -> 3000 | AG12: 250 | AH12: 250 | AI12: 250 | AJ12: 250 | AK12: 250 | AL12: 250 | AM12: 250 | AN12: 250 | AO12: 250 | AP12: 250 | AQ12: 250 | AR12: 250 | AS12: 250 | BG12: =SUM(AU12:BF12) -> 0 | BU12: =SUM(BI12:BT12) -> 0 | CI12: =SUM(BW12:CH12) -> 0 | CW12: =SUM(CK12:CV12) -> 0 | DK12: =SUM(CY12:DJ12) -> 0 | DY12: =SUM(DM12:DX12) -> 0 | EM12: =SUM(EA12:EL12) -> 0
C13: Other | Q13: =SUM(E13:P13) -> 0 | S13: 0 | T13: 0 | U13: 0 | V13: 0 | W13: 0 | X13: 0 | Y13: 0 | Z13: 0 | AA13: 0 | AB13: 0 | AC13: 0 | AD13: 0 | AE13: =SUM(S13:AD13) -> 0 | AG13: 0 | AH13: 0 | AI13: 0 | AJ13: 0 | AK13: 0 | AL13: 0 | AM13: 0 | AN13: 0 | AO13: 0 | AP13: 0 | AQ13: 0 | AR13: 0 | AS13: 0 | BG13: =SUM(AU13:BF13) -> 0 | BU13: =SUM(BI13:BT13) -> 0 | CI13: =SUM(BW13:CH13) -> 0 | CW13: =SUM(CK13:CV13) -> 0 | DK13: =SUM(CY13:DJ13) -> 0 | DY13: =SUM(DM13:DX13) -> 0 | EM13: =SUM(EA13:EL13) -> 0
C14: Enter Income Category… | Q14: =SUM(E14:P14) -> 0 | AE14: =SUM(S14:AD14) -> 0 | AS14: =SUM(AG14:AR14) -> 0 | BG14: =SUM(AU14:BF14) -> 0 | BU14: =SUM(BI14:BT14) -> 0 | CI14: =SUM(BW14:CH14) -> 0 | CW14: =SUM(CK14:CV14) -> 0 | DK14: =SUM(CY14:DJ14) -> 0 | DY14: =SUM(DM14:DX14) -> 0 | EM14: =SUM(EA14:EL14) -> 0
C15: Enter Income Category… | Q15: =SUM(E15:P15) -> 0 | AE15: =SUM(S15:AD15) -> 0 | AS15: =SUM(AG15:AR15) -> 0 | BG15: =SUM(AU15:BF15) -> 0 | BU15: =SUM(BI15:BT15) -> 0 | CI15: =SUM(BW15:CH15) -> 0 | CW15: =SUM(CK15:CV15) -> 0 | DK15: =SUM(CY15:DJ15) -> 0 | DY15: =SUM(DM15:DX15) -> 0 | EM15: =SUM(EA15:EL15) -> 0
C16: Enter Income Category… | Q16: =SUM(E16:P16) -> 0 | AE16: =SUM(S16:AD16) -> 0 | AS16: =SUM(AG16:AR16) -> 0 | BG16: =SUM(AU16:BF16) -> 0 | BU16: =SUM(BI16:BT16) -> 0 | CI16: =SUM(BW16:CH16) -> 0 | CW16: =SUM(CK16:CV16) -> 0 | DK16: =SUM(CY16:DJ16) -> 0 | DY16: =SUM(DM16:DX16) -> 0 | EM16: =SUM(EA16:EL16) -> 0
C17: Enter Income Category… | Q17: =SUM(E17:P17) -> 0 | AE17: =SUM(S17:AD17) -> 0 | AS17: =SUM(AG17:AR17) -> 0 | BG17: =SUM(AU17:BF17) -> 0 | BU17: =SUM(BI17:BT17) -> 0 | CI17: =SUM(BW17:CH17) -> 0 | CW17: =SUM(CK17:CV17) -> 0 | DK17: =SUM(CY17:DJ17) -> 0 | DY17: =SUM(DM17:DX17) -> 0 | EM17: =SUM(EA17:EL17) -> 0
C18: Enter Income Category… | Q18: =SUM(E18:P18) -> 0 | AE18: =SUM(S18:AD18) -> 0 | AS18: =SUM(AG18:AR18) -> 0 | BG18: =SUM(AU18:BF18) -> 0 | BU18: =SUM(BI18:BT18) -> 0 | CI18: =SUM(BW18:CH18) -> 0 | CW18: =SUM(CK18:CV18) -> 0 | DK18: =SUM(CY18:DJ18) -> 0 | DY18: =SUM(DM18:DX18) -> 0 | EM18: =SUM(EA18:EL18) -> 0
C19: Enter Income Category… | Q19: =SUM(E19:P19) -> 0 | AE19: =SUM(S19:AD19) -> 0 | AS19: =SUM(AG19:AR19) -> 0 | BG19: =SUM(AU19:BF19) -> 0 | BU19: =SUM(BI19:BT19) -> 0 | CI19: =SUM(BW19:CH19) -> 0 | CW19: =SUM(CK19:CV19) -> 0 | DK19: =SUM(CY19:DJ19) -> 0 | DY19: =SUM(DM19:DX19) -> 0 | EM19: =SUM(EA19:EL19) -> 0
C20: Total | E20: {=SUM(INDIRECT(ADDRESS(income_min_row, COLUMN()) & ":" & ADDRESS(income_max_row, COLUMN())))} -> 0 | F20: {=SUM(INDIRECT(ADDRESS(income_min_row, COLUMN()) & ":" & ADDRESS(income_max_row, COLUMN())))} -> 0 | G20: {=SUM(INDIRECT(ADDRESS(income_min_row, COLUMN()) & ":" & ADDRESS(income_max_row, COLUMN())))} -> 0 | H20: {=SUM(INDIRECT(ADDRESS(income_min_row, COLUMN()) & ":" & ADDRESS(income_max_row, COLUMN())))} -> 0 | I20: {=SUM(INDIRECT(ADDRESS(income_min_row, COLUMN()) & ":" & ADDRESS(income_max_row, COLUMN())))} -> 0 | J20: {=SUM(INDIRECT(ADDRESS(income_min_row, COLUMN()) & ":" & ADDRESS(income_max_row, COLUMN())))} -> 7300 | K20: {=SUM(INDIRECT(ADDRESS(income_min_row, COLUMN()) & ":" & ADDRESS(income_max_row, COLUMN())))} -> 7300 | L20: {=SUM(INDIRECT(ADDRESS(income_min_row, COLUMN()) & ":" & ADDRESS(income_max_row, COLUMN())))} -> 7300 | ... Q20: {=SUM(INDIRECT(ADDRESS(income_min_row, COLUMN()) & ":" & ADDRESS(income_max_row, COLUMN())))} -> 53600 | S20: {=SUM(INDIRECT(ADDRESS(income_min_row, COLUMN()) & ":" & ADDRESS(income_max_row, COLUMN())))} -> 7750 | T20: {=SUM(INDIRECT(ADDRESS(income_min_row, COLUMN()) & ":" & ADDRESS(income_max_row, COLUMN())))} -> 7750 | U20: {=SUM(INDIRECT(ADDRESS(income_min_row, COLUMN()) & ":" & ADDRESS(income_max_row, COLUMN())))} -> 7750 | V20: {=SUM(INDIRECT(ADDRESS(income_min_row, COLUMN()) & ":" & ADDRESS(income_max_row, COLUMN())))} -> 7750 | W20: {=SUM(INDIRECT(ADDRESS(income_min_row, COLUMN()) & ":" & ADDRESS(income_max_row, COLUMN())))} -> 7750 | X20: {=SUM(INDIRECT(ADDRESS(income_min_row, COLUMN()) & ":" & ADDRESS(income_max_row, COLUMN())))} -> 7750 | Y20: {=SUM(INDIRECT(ADDRESS(income_min_row, COLUMN()) & ":" & ADDRESS(income_max_row, COLUMN())))} -> 7950 | Z20: {=SUM(INDIRECT(ADDRESS(income_min_row, COLUMN()) & ":" & ADDRESS(income_max_row, COLUMN())))} -> 7950 | ... AE20: {=SUM(INDIRECT(ADDRESS(income_min_row, COLUMN()) & ":" & ADDRESS(income_max_row, COLUMN())))} -> 94200 | AG20: {=SUM(INDIRECT(ADDRESS(income_min_row, COLUMN()) & ":" & ADDRESS(income_max_row, COLUMN())))} -> 7950 | AH20: {=SUM(INDIRECT(ADDRESS(income_min_row, COLUMN()) & ":" & ADDRESS(income_max_row, COLUMN())))} -> 7950 | AI20: {=SUM(INDIRECT(ADDRESS(income_min_row, COLUMN()) & ":" & ADDRESS(income_max_row, COLUMN())))} -> 7950 | AJ20: {=SUM(INDIRECT(ADDRESS(income_min_row, COLUMN()) & ":" & ADDRESS(income_max_row, COLUMN())))} -> 7950 | AK20: {=SUM(INDIRECT(ADDRESS(income_min_row, COLUMN()) & ":" & ADDRESS(income_max_row, COLUMN())))} -> 7950 | AL20: {=SUM(INDIRECT(ADDRESS(income_min_row, COLUMN()) & ":" & ADDRESS(income_max_row, COLUMN())))} -> 7950 | AM20: {=SUM(INDIRECT(ADDRESS(income_min_row, COLUMN()) & ":" & ADDRESS(income_max_row, COLUMN())))} -> 7950 | AN20: {=SUM(INDIRECT(ADDRESS(income_min_row, COLUMN()) & ":" & ADDRESS(income_max_row, COLUMN())))} -> 7950 | ... AS20: {=SUM(INDIRECT(ADDRESS(income_min_row, COLUMN()) & ":" & ADDRESS(income_max_row, COLUMN())))} -> 7950 | AU20: {=SUM(INDIRECT(ADDRESS(income_min_row, COLUMN()) & ":" & ADDRESS(income_max_row, COLUMN())))} -> 0 | AV20: {=SUM(INDIRECT(ADDRESS(income_min_row, COLUMN()) & ":" & ADDRESS(income_max_row, COLUMN())))} -> 0 | AW20: {=SUM(INDIRECT(ADDRESS(income_min_row, COLUMN()) & ":" & ADDRESS(income_max_row, COLUMN())))} -> 0 | AX20: {=SUM(INDIRECT(ADDRESS(income_min_row, COLUMN()) & ":" & ADDRESS(income_max_row, COLUMN())))} -> 0 | AY20: {=SUM(INDIRECT(ADDRESS(income_min_row, COLUMN()) & ":" & ADDRESS(income_max_row, COLUMN())))} -> 0 | AZ20: {=SUM(INDIRECT(ADDRESS(income_min_row, COLUMN()) & ":" & ADDRESS(income_max_row, COLUMN())))} -> 0 | BA20: {=SUM(INDIRECT(ADDRESS(income_min_row, COLUMN()) & ":" & ADDRESS(income_max_row, COLUMN())))} -> 0 | BB20: {=SUM(INDIRECT(ADDRESS(income_min_row, COLUMN()) & ":" & ADDRESS(income_max_row, COLUMN())))} -> 0 | ... BG20: {=SUM(INDIRECT(ADDRESS(income_min_row, COLUMN()) & ":" & ADDRESS(income_max_row, COLUMN())))} -> 0 | BI20: {=SUM(INDIRECT(ADDRESS(income_min_row, COLUMN()) & ":" & ADDRESS(income_max_row, COLUMN())))} -> 0 | BJ20: {=SUM(INDIRECT(ADDRESS(income_min_row, COLUMN()) & ":" & ADDRESS(income_max_row, COLUMN())))} -> 0 | BK20: {=SUM(INDIRECT(ADDRESS(income_min_row, COLUMN()) & ":" & ADDRESS(income_max_row, COLUMN())))} -> 0 | BL20: {=SUM(INDIRECT(ADDRESS(income_min_row, COLUMN()) & ":" & ADDRESS(income_max_row, COLUMN())))} -> 0 | BM20: {=SUM(INDIRECT(ADDRESS(income_min_row, COLUMN()) & ":" & ADDRESS(income_max_row, COLUMN())))} -> 0 | BN20: {=SUM(INDIRECT(ADDRESS(income_min_row, COLUMN()) & ":" & ADDRESS(income_max_row, COLUMN())))} -> 0 | BO20: {=SUM(INDIRECT(ADDRESS(income_min_row, COLUMN()) & ":" & ADDRESS(income_max_row, COLUMN())))} -> 0 | BP20: {=SUM(INDIRECT(ADDRESS(income_min_row, COLUMN()) & ":" & ADDRESS(income_max_row, COLUMN())))} -> 0 | ... BU20: {=SUM(INDIRECT(ADDRESS(income_min_row, COLUMN()) & ":" & ADDRESS(income_max_row, COLUMN())))} -> 0 | BW20: {=SUM(INDIRECT(ADDRESS(income_min_row, COLUMN()) & ":" & ADDRESS(income_max_row, COLUMN())))} -> 0 | BX20: {=SUM(INDIRECT(ADDRESS(income_min_row, COLUMN()) & ":" & ADDRESS(income_max_row, COLUMN())))} -> 0 | BY20: {=SUM(INDIRECT(ADDRESS(income_min_row, COLUMN()) & ":" & ADDRESS(income_max_row, COLUMN())))} -> 0 | BZ20: {=SUM(INDIRECT(ADDRESS(income_min_row, COLUMN()) & ":" & ADDRESS(income_max_row, COLUMN())))} -> 0 | CA20: {=SUM(INDIRECT(ADDRESS(income_min_row, COLUMN()) & ":" & ADDRESS(income_max_row, COLUMN())))} -> 0 | CB20: {=SUM(INDIRECT(ADDRESS(income_min_row, COLUMN()) & ":" & ADDRESS(income_max_row, COLUMN())))} -> 0 | CC20: {=SUM(INDIRECT(ADDRESS(income_min_row, COLUMN()) & ":" & ADDRESS(income_max_row, COLUMN())))} -> 0 | CD20: {=SUM(INDIRECT(ADDRESS(income_min_row, COLUMN()) & ":" & ADDRESS(income_max_row, COLUMN())))} -> 0 | ... CI20: {=SUM(INDIRECT(ADDRESS(income_min_row, COLUMN()) & ":" & ADDRESS(income_max_row, COLUMN())))} -> 0 | CK20: {=SUM(INDIRECT(ADDRESS(income_min_row, COLUMN()) & ":" & ADDRESS(income_max_row, COLUMN())))} -> 0 | CL20: {=SUM(INDIRECT(ADDRESS(income_min_row, COLUMN()) & ":" & ADDRESS(income_max_row, COLUMN())))} -> 0 | CM20: {=SUM(INDIRECT(ADDRESS(income_min_row, COLUMN()) & ":" & ADDRESS(income_max_row, COLUMN())))} -> 0 | CN20: {=SUM(INDIRECT(ADDRESS(income_min_row, COLUMN()) & ":" & ADDRESS(income_max_row, COLUMN())))} -> 0 | CO20: {=SUM(INDIRECT(ADDRESS(income_min_row, COLUMN()) & ":" & ADDRESS(income_max_row, COLUMN())))} -> 0 | CP20: {=SUM(INDIRECT(ADDRESS(income_min_row, COLUMN()) & ":" & ADDRESS(income_max_row, COLUMN())))} -> 0 | CQ20: {=SUM(INDIRECT(ADDRESS(income_min_row, COLUMN()) & ":" & ADDRESS(income_max_row, COLUMN())))} -> 0 | CR20: {=SUM(INDIRECT(ADDRESS(income_min_row, COLUMN()) & ":" & ADDRESS(income_max_row, COLUMN())))} -> 0 | ... CW20: {=SUM(INDIRECT(ADDRESS(income_min_row, COLUMN()) & ":" & ADDRESS(income_max_row, COLUMN())))} -> 0 | CY20: {=SUM(INDIRECT(ADDRESS(income_min_row, COLUMN()) & ":" & ADDRESS(income_max_row, COLUMN())))} -> 0 | CZ20: {=SUM(INDIRECT(ADDRESS(income_min_row, COLUMN()) & ":" & ADDRESS(income_max_row, COLUMN())))} -> 0 | DA20: {=SUM(INDIRECT(ADDRESS(income_min_row, COLUMN()) & ":" & ADDRESS(income_max_row, COLUMN())))} -> 0 | DB20: {=SUM(INDIRECT(ADDRESS(income_min_row, COLUMN()) & ":" & ADDRESS(income_max_row, COLUMN())))} -> 0 | DC20: {=SUM(INDIRECT(ADDRESS(income_min_row, COLUMN()) & ":" & ADDRESS(income_max_row, COLUMN())))} -> 0 | DD20: {=SUM(INDIRECT(ADDRESS(income_min_row, COLUMN()) & ":" & ADDRESS(income_max_row, COLUMN())))} -> 0 | DE20: {=SUM(INDIRECT(ADDRESS(income_min_row, COLUMN()) & ":" & ADDRESS(income_max_row, COLUMN())))} -> 0 | DF20: {=SUM(INDIRECT(ADDRESS(income_min_row, COLUMN()) & ":" & ADDRESS(income_max_row, COLUMN())))} -> 0 | ... DK20: {=SUM(INDIRECT(ADDRESS(income_min_row, COLUMN()) & ":" & ADDRESS(income_max_row, COLUMN())))} -> 0 | DM20: {=SUM(INDIRECT(ADDRESS(income_min_row, COLUMN()) & ":" & ADDRESS(income_max_row, COLUMN())))} -> 0 | DN20: {=SUM(INDIRECT(ADDRESS(income_min_row, COLUMN()) & ":" & ADDRESS(income_max_row, COLUMN())))} -> 0 | DO20: {=SUM(INDIRECT(ADDRESS(income_min_row, COLUMN()) & ":" & ADDRESS(income_max_row, COLUMN())))} -> 0 | DP20: {=SUM(INDIRECT(ADDRESS(income_min_row, COLUMN()) & ":" & ADDRESS(income_max_row, COLUMN())))} -> 0 | DQ20: {=SUM(INDIRECT(ADDRESS(income_min_row, COLUMN()) & ":" & ADDRESS(income_max_row, COLUMN())))} -> 0 | DR20: {=SUM(INDIRECT(ADDRESS(income_min_row, COLUMN()) & ":" & ADDRESS(income_max_row, COLUMN())))} -> 0 | DS20: {=SUM(INDIRECT(ADDRESS(income_min_row, COLUMN()) & ":" & ADDRESS(income_max_row, COLUMN())))} -> 0 | DT20: {=SUM(INDIRECT(ADDRESS(income_min_row, COLUMN()) & ":" & ADDRESS(income_max_row, COLUMN())))} -> 0 | ... DY20: {=SUM(INDIRECT(ADDRESS(income_min_row, COLUMN()) & ":" & ADDRESS(income_max_row, COLUMN())))} -> 0 | EA20: {=SUM(INDIRECT(ADDRESS(income_min_row, COLUMN()) & ":" & ADDRESS(income_max_row, COLUMN())))} -> 0 | EB20: {=SUM(INDIRECT(ADDRESS(income_min_row, COLUMN()) & ":" & ADDRESS(income_max_row, COLUMN())))} -> 0 | EC20: {=SUM(INDIRECT(ADDRESS(income_min_row, COLUMN()) & ":" & ADDRESS(income_max_row, COLUMN())))} -> 0 | ED20: {=SUM(INDIRECT(ADDRESS(income_min_row, COLUMN()) & ":" & ADDRESS(income_max_row, COLUMN())))} -> 0 | EE20: {=SUM(INDIRECT(ADDRESS(income_min_row, COLUMN()) & ":" & ADDRESS(income_max_row, COLUMN())))} -> 0 | EF20: {=SUM(INDIRECT(ADDRESS(income_min_row, COLUMN()) & ":" & ADDRESS(income_max_row, COLUMN())))} -> 0 | EG20: {=SUM(INDIRECT(ADDRESS(income_min_row, COLUMN()) & ":" & ADDRESS(income_max_row, COLUMN())))} -> 0 | EH20: {=SUM(INDIRECT(ADDRESS(income_min_row, COLUMN()) & ":" & ADDRESS(income_max_row, COLUMN())))} -> 0 | ... EM20: {=SUM(INDIRECT(ADDRESS(income_min_row, COLUMN()) & ":" & ADDRESS(income_max_row, COLUMN())))} -> 0
C22: Expenses | E22: =DATE(E$5,1,1) -> 45292 | F22: =DATE(E$5,2,1) -> 45323 | G22: =DATE(E$5,3,1) -> 45352 | H22: =DATE(E$5,4,1) -> 45383 | I22: =DATE(E$5,5,1) -> 45413 | J22: =DATE(E$5,6,1) -> 45444 | K22: =DATE(E$5,7,1) -> 45474 | L22: =DATE(E$5,8,1) -> 45505 | M22: =DATE(E$5,9,1) -> 45536 | N22: =DATE(E$5,10,1) -> 45566 | O22: =DATE(E$5,11,1) -> 45597 | P22: =DATE(E$5,12,1) -> 45627 | Q22: =E$5 -> 2024 | S22: =DATE(S$5,1,1) -> 45658 | T22: =DATE(S$5,2,1) -> 45689 | U22: =DATE(S$5,3,1) -> 45717 | V22: =DATE(S$5,4,1) -> 45748 | W22: =DATE(S$5,5,1) -> 45778 | X22: =DATE(S$5,6,1) -> 45809 | Y22: =DATE(S$5,7,1) -> 45839 | Z22: =DATE(S$5,8,1) -> 45870 | AA22: =DATE(S$5,9,1) -> 45901 | AB22: =DATE(S$5,10,1) -> 45931 | AC22: =DATE(S$5,11,1) -> 45962 | AD22: =DATE(S$5,12,1) -> 45992 | AE22: =S$5 -> 2025 | AG22: =DATE(AG$5,1,1) -> 46023 | AH22: =DATE(AG$5,2,1) -> 46054 | AI22: =DATE(AG$5,3,1) -> 46082 | AJ22: =DATE(AG$5,4,1) -> 46113 | AK22: =DATE(AG$5,5,1) -> 46143 | AL22: =DATE(AG$5,6,1) -> 46174 | AM22: =DATE(AG$5,7,1) -> 46204 | AN22: =DATE(AG$5,8,1) -> 46235 | AO22: =DATE(AG$5,9,1) -> 46266 | AP22: =DATE(AG$5,10,1) -> 46296 | AQ22: =DATE(AG$5,11,1) -> 46327 | AR22: =DATE(AG$5,12,1) -> 46357 | AS22: =AG$5 -> 2026 | AU22: =DATE(AU$5,1,1) -> 46388 | AV22: =DATE(AU$5,2,1) -> 46419 | AW22: =DATE(AU$5,3,1) -> 46447 | AX22: =DATE(AU$5,4,1) -> 46478 | AY22: =DATE(AU$5,5,1) -> 46508 | AZ22: =DATE(AU$5,6,1) -> 46539 | BA22: =DATE(AU$5,7,1) -> 46569 | BB22: =DATE(AU$5,8,1) -> 46600 | BC22: =DATE(AU$5,9,1) -> 46631 | BD22: =DATE(AU$5,10,1) -> 46661 | BE22: =DATE(AU$5,11,1) -> 46692 | BF22: =DATE(AU$5,12,1) -> 46722 | BG22: =AU$5 -> 2027 | BI22: =DATE(BI$5,1,1) -> 46753 | BJ22: =DATE(BI$5,2,1) -> 46784 | BK22: =DATE(BI$5,3,1) -> 46813 | BL22: =DATE(BI$5,4,1) -> 46844 | BM22: =DATE(BI$5,5,1) -> 46874 | BN22: =DATE(BI$5,6,1) -> 46905 | BO22: =DATE(BI$5,7,1) -> 46935 | BP22: =DATE(BI$5,8,1) -> 46966 | BQ22: =DATE(BI$5,9,1) -> 46997 | BR22: =DATE(BI$5,10,1) -> 47027 | BS22: =DATE(BI$5,11,1) -> 47058 | BT22: =DATE(BI$5,12,1) -> 47088 | BU22: =BI$5 -> 2028 | BW22: =DATE(BW$5,1,1) -> 47119 | BX22: =DATE(BW$5,2,1) -> 47150 | BY22: =DATE(BW$5,3,1) -> 47178 | BZ22: =DATE(BW$5,4,1) -> 47209 | CA22: =DATE(BW$5,5,1) -> 47239 | CB22: =DATE(BW$5,6,1) -> 47270 | CC22: =DATE(BW$5,7,1) -> 47300 | CD22: =DATE(BW$5,8,1) -> 47331 | CE22: =DATE(BW$5,9,1) -> 47362 | CF22: =DATE(BW$5,10,1) -> 47392 | CG22: =DATE(BW$5,11,1) -> 47423 | CH22: =DATE(BW$5,12,1) -> 47453 | CI22: =BW$5 -> 2029 | CK22: =DATE(CK$5,1,1) -> 47484 | CL22: =DATE(CK$5,2,1) -> 47515 | CM22: =DATE(CK$5,3,1) -> 47543 | CN22: =DATE(CK$5,4,1) -> 47574 | CO22: =DATE(CK$5,5,1) -> 47604 | CP22: =DATE(CK$5,6,1) -> 47635 | CQ22: =DATE(CK$5,7,1) -> 47665 | CR22: =DATE(CK$5,8,1) -> 47696 | CS22: =DATE(CK$5,9,1) -> 47727 | CT22: =DATE(CK$5,10,1) -> 47757 | CU22: =DATE(CK$5,11,1) -> 47788 | CV22: =DATE(CK$5,12,1) -> 47818 | CW22: =CK$5 -> 2030 | CY22: =DATE(CY$5,1,1) -> 47849 | CZ22: =DATE(CY$5,2,1) -> 47880 | DA22: =DATE(CY$5,3,1) -> 47908 | DB22: =DATE(CY$5,4,1) -> 47939 | DC22: =DATE(CY$5,5,1) -> 47969 | DD22: =DATE(CY$5,6,1) -> 48000 | DE22: =DATE(CY$5,7,1) -> 48030 | DF22: =DATE(CY$5,8,1) -> 48061 | DG22: =DATE(CY$5,9,1) -> 48092 | DH22: =DATE(CY$5,10,1) -> 48122 | DI22: =DATE(CY$5,11,1) -> 48153 | DJ22: =DATE(CY$5,12,1) -> 48183 | DK22: =CY$5 -> 2031 | DM22: =DATE(DM$5,1,1) -> 48214 | DN22: =DATE(DM$5,2,1) -> 48245 | DO22: =DATE(DM$5,3,1) -> 48274 | DP22: =DATE(DM$5,4,1) -> 48305 | DQ22: =DATE(DM$5,5,1) -> 48335 | DR22: =DATE(DM$5,6,1) -> 48366 | DS22: =DATE(DM$5,7,1) -> 48396 | DT22: =DATE(DM$5,8,1) -> 48427 | DU22: =DATE(DM$5,9,1) -> 48458 | DV22: =DATE(DM$5,10,1) -> 48488 | DW22: =DATE(DM$5,11,1) -> 48519 | DX22: =DATE(DM$5,12,1) -> 48549 | DY22: =DM$5 -> 2032 | EA22: =DATE(EA$5,1,1) -> 48580 | EB22: =DATE(EA$5,2,1) -> 48611 | EC22: =DATE(EA$5,3,1) -> 48639 | ED22: =DATE(EA$5,4,1) -> 48670 | EE22: =DATE(EA$5,5,1) -> 48700 | EF22: =DATE(EA$5,6,1) -> 48731 | EG22: =DATE(EA$5,7,1) -> 48761 | EH22: =DATE(EA$5,8,1) -> 48792 | EI22: =DATE(EA$5,9,1) -> 48823 | EJ22: =DATE(EA$5,10,1) -> 48853 | EK22: =DATE(EA$5,11,1) -> 48884 | EL22: =DATE(EA$5,12,1) -> 48914 | EM22: =EA$5 -> 2033
C23: Groceries | J23: 400 | K23: 400 | L23: 400 | M23: 400 | N23: 400 | O23: 400 | P23: 400 | Q23: =SUM(E23:P23) -> 2800 | S23: 700 | T23: 700 | U23: 700 | V23: 700 | W23: 700 | X23: 700 | Y23: 700 | Z23: 700 | AA23: 700 | AB23: 700 | AC23: 700 | AD23: 700 | AE23: =SUM(S23:AD23) -> 8400 | AG23: 480 | BG23: =SUM(AU23:BF23) -> 0 | BU23: =SUM(BI23:BT23) -> 0 | CI23: =SUM(BW23:CH23) -> 0 | CW23: =SUM(CK23:CV23) -> 0 | DK23: =SUM(CY23:DJ23) -> 0 | DY23: =SUM(DM23:DX23) -> 0 | EM23: =SUM(EA23:EL23) -> 0
C24: Eat out | J24: 600 | K24: 600 | L24: 600 | M24: 600 | N24: 600 | O24: 600 | P24: 600 | Q24: =SUM(E24:P24) -> 4200 | S24: 400 | T24: 400 | U24: 400 | V24: 400 | W24: 400 | X24: 400 | Y24: 400 | Z24: 400 | AA24: 400 | AB24: 400 | AC24: 400 | AD24: 400 | AE24: =SUM(S24:AD24) -> 4800 | AG24: 580 | BG24: =SUM(AU24:BF24) -> 0 | BU24: =SUM(BI24:BT24) -> 0 | CI24: =SUM(BW24:CH24) -> 0 | CW24: =SUM(CK24:CV24) -> 0 | DK24: =SUM(CY24:DJ24) -> 0 | DY24: =SUM(DM24:DX24) -> 0 | EM24: =SUM(EA24:EL24) -> 0
C25: Fun | Q25: =SUM(E25:P25) -> 0 | S25: 150 | T25: 250 | U25: 250 | V25: 250 | W25: 250 | X25: 250 | Y25: 250 | Z25: 250 | AA25: 250 | AB25: 250 | AC25: 250 | AD25: 250 | AE25: =SUM(S25:AD25) -> 2900 | AG25: 170 | AS25: =SUM(AG25:AR25) -> 170 | BG25: =SUM(AU25:BF25) -> 0 | BU25: =SUM(BI25:BT25) -> 0 | CI25: =SUM(BW25:CH25) -> 0 | CW25: =SUM(CK25:CV25) -> 0 | DK25: =SUM(CY25:DJ25) -> 0 | DY25: =SUM(DM25:DX25) -> 0 | EM25: =SUM(EA25:EL25) -> 0
C26: Medical | J26: 200 | K26: 200 | L26: 200 | M26: 200 | N26: 200 | O26: 200 | P26: 200 | Q26: =SUM(E26:P26) -> 1400 | S26: 150 | T26: 150 | U26: 150 | V26: 150 | W26: 150 | X26: 150 | Y26: 150 | Z26: 150 | AA26: 150 | AB26: 150 | AC26: 150 | AD26: 150 | AE26: =SUM(S26:AD26) -> 1800 | AG26: 140 | BG26: =SUM(AU26:BF26) -> 0 | BU26: =SUM(BI26:BT26) -> 0 | CI26: =SUM(BW26:CH26) -> 0 | CW26: =SUM(CK26:CV26) -> 0 | DK26: =SUM(CY26:DJ26) -> 0 | DY26: =SUM(DM26:DX26) -> 0 | EM26: =SUM(EA26:EL26) -> 0
C27: Baby | J27: 250 | K27: 250 | L27: 250 | M27: 250 | N27: 250 | O27: 250 | P27: 250 | Q27: =SUM(E27:P27) -> 1750 | S27: 300 | T27: 300 | U27: 300 | V27: 300 | W27: 300 | X27: 300 | Y27: 300 | Z27: 300 | AA27: 300 | AB27: 300 | AC27: 300 | AD27: 300 | AE27: =SUM(S27:AD27) -> 3600 | AG27: 290 | BG27: =SUM(AU27:BF27) -> 0 | BU27: =SUM(BI27:BT27) -> 0 | CI27: =SUM(BW27:CH27) -> 0 | CW27: =SUM(CK27:CV27) -> 0 | DK27: =SUM(CY27:DJ27) -> 0 | DY27: =SUM(DM27:DX27) -> 0 | EM27: =SUM(EA27:EL27) -> 0
C28: Body care | J28: 150 | K28: 150 | L28: 150 | M28: 150 | N28: 150 | O28: 150 | P28: 150 | Q28: =SUM(E28:P28) -> 1050 | S28: 100 | T28: 300 | U28: 300 | V28: 300 | W28: 300 | X28: 300 | Y28: 300 | Z28: 300 | AA28: 300 | AB28: 300 | AC28: 300 | AD28: 300 | AE28: =SUM(S28:AD28) -> 3400 | AG28: 270 | BG28: =SUM(AU28:BF28) -> 0 | BU28: =SUM(BI28:BT28) -> 0 | CI28: =SUM(BW28:CH28) -> 0 | CW28: =SUM(CK28:CV28) -> 0 | DK28: =SUM(CY28:DJ28) -> 0 | DY28: =SUM(DM28:DX28) -> 0 | EM28: =SUM(EA28:EL28) -> 0
C29: Maya | J29: 100 | K29: 100 | L29: 100 | M29: 100 | N29: 100 | O29: 100 | P29: 100 | Q29: =SUM(E29:P29) -> 700 | S29: 50 | T29: 50 | U29: 50 | V29: 50 | W29: 50 | X29: 50 | Y29: 50 | Z29: 50 | AA29: 50 | AB29: 50 | AC29: 50 | AD29: 50 | AE29: =SUM(S29:AD29) -> 600 | AG29: 50 | BG29: =SUM(AU29:BF29) -> 0 | BU29: =SUM(BI29:BT29) -> 0 | CI29: =SUM(BW29:CH29) -> 0 | CW29: =SUM(CK29:CV29) -> 0 | DK29: =SUM(CY29:DJ29) -> 0 | DY29: =SUM(DM29:DX29) -> 0 | EM29: =SUM(EA29:EL29) -> 0
C30: Clothes | J30: 200 | K30: 200 | L30: 200 | M30: 200 | N30: 200 | O30: 200 | P30: 200 | Q30: =SUM(E30:P30) -> 1400 | S30: 200 | T30: 200 | U30: 200 | V30: 200 | W30: 200 | X30: 200 | Y30: 200 | Z30: 200 | AA30: 200 | AB30: 200 | AC30: 200 | AD30: 200 | AE30: =SUM(S30:AD30) -> 2400 | AG30: 210 | BG30: =SUM(AU30:BF30) -> 0 | BU30: =SUM(BI30:BT30) -> 0 | CI30: =SUM(BW30:CH30) -> 0 | CW30: =SUM(CK30:CV30) -> 0 | DK30: =SUM(CY30:DJ30) -> 0 | DY30: =SUM(DM30:DX30) -> 0 | EM30: =SUM(EA30:EL30) -> 0
C31: Hobbies | J31: 50 | K31: 50 | L31: 50 | M31: 50 | N31: 50 | O31: 50 | P31: 50 | Q31: =SUM(E31:P31) -> 350 | S31: 100 | T31: 100 | U31: 100 | V31: 100 | W31: 100 | X31: 100 | Y31: 100 | Z31: 100 | AA31: 100 | AB31: 100 | AC31: 100 | AD31: 100 | AE31: =SUM(S31:AD31) -> 1200 | AG31: 50 | BG31: =SUM(AU31:BF31) -> 0 | BU31: =SUM(BI31:BT31) -> 0 | CI31: =SUM(BW31:CH31) -> 0 | CW31: =SUM(CK31:CV31) -> 0 | DK31: =SUM(CY31:DJ31) -> 0 | DY31: =SUM(DM31:DX31) -> 0 | EM31: =SUM(EA31:EL31) -> 0
C32: Home improvements | J32: 150 | K32: 150 | L32: 150 | M32: 150 | N32: 150 | O32: 150 | P32: 150 | Q32: =SUM(E32:P32) -> 1050 | S32: 300 | T32: 300 | U32: 300 | V32: 300 | W32: 300 | X32: 300 | Y32: 300 | Z32: 300 | AA32: 300 | AB32: 300 | AC32: 300 | AD32: 300 | AE32: =SUM(S32:AD32) -> 3600 | AG32: 290 | BG32: =SUM(AU32:BF32) -> 0 | BU32: =SUM(BI32:BT32) -> 0 | CI32: =SUM(BW32:CH32) -> 0 | CW32: =SUM(CK32:CV32) -> 0 | DK32: =SUM(CY32:DJ32) -> 0 | DY32: =SUM(DM32:DX32) -> 0 | EM32: =SUM(EA32:EL32) -> 0
C33: Mortgage | J33: 3220 | K33: 3220 | L33: 3220 | M33: 3220 | N33: 3220 | O33: 3220 | P33: 3220 | Q33: =SUM(E33:P33) -> 22540 | S33: 3215 | T33: 3215 | U33: 3215 | V33: 3215 | W33: 3215 | X33: 3215 | Y33: 3215 | Z33: 3215 | AA33: 3215 | AB33: 3215 | AC33: 3215 | AD33: 3215 | AE33: =SUM(S33:AD33) -> 38580 | AG33: 3220 | BG33: =SUM(AU33:BF33) -> 0 | BU33: =SUM(BI33:BT33) -> 0 | CI33: =SUM(BW33:CH33) -> 0 | CW33: =SUM(CK33:CV33) -> 0 | DK33: =SUM(CY33:DJ33) -> 0 | DY33: =SUM(DM33:DX33) -> 0 | EM33: =SUM(EA33:EL33) -> 0
C34: Utilities | J34: 350 | K34: 350 | L34: 350 | M34: 350 | N34: 350 | O34: 350 | P34: 350 | Q34: =SUM(E34:P34) -> 2450 | S34: 350 | T34: 350 | U34: 350 | V34: 350 | W34: 350 | X34: 350 | Y34: 350 | Z34: 350 | AA34: 350 | AB34: 350 | AC34: 350 | AD34: 350 | AE34: =SUM(S34:AD34) -> 4200 | AG34: 530 | BG34: =SUM(AU34:BF34) -> 0 | BU34: =SUM(BI34:BT34) -> 0 | CI34: =SUM(BW34:CH34) -> 0 | CW34: =SUM(CK34:CV34) -> 0 | DK34: =SUM(CY34:DJ34) -> 0 | DY34: =SUM(DM34:DX34) -> 0 | EM34: =SUM(EA34:EL34) -> 0
C35: Subscriptions | J35: 100 | K35: 100 | L35: 100 | M35: 100 | N35: 100 | O35: 100 | P35: 100 | Q35: =SUM(E35:P35) -> 700 | S35: 100 | T35: 180 | U35: 180 | V35: 180 | W35: 180 | X35: 180 | Y35: 180 | Z35: 180 | AA35: 180 | AB35: 180 | AC35: 180 | AD35: 180 | AE35: =SUM(S35:AD35) -> 2080 | AG35: 180 | BG35: =SUM(AU35:BF35) -> 0 | BU35: =SUM(BI35:BT35) -> 0 | CI35: =SUM(BW35:CH35) -> 0 | CW35: =SUM(CK35:CV35) -> 0 | DK35: =SUM(CY35:DJ35) -> 0 | DY35: =SUM(DM35:DX35) -> 0 | EM35: =SUM(EA35:EL35) -> 0
C36: Vacation | J36: 150 | K36: 150 | L36: 150 | M36: 150 | N36: 150 | O36: 150 | P36: 150 | Q36: =SUM(E36:P36) -> 1050 | S36: 0 | T36: 600 | U36: 0 | V36: 0 | W36: 0 | X36: 0 | Y36: 0 | Z36: 0 | AA36: 0 | AB36: 0 | AC36: 0 | AD36: 0 | AE36: =SUM(S36:AD36) -> 600 | AG36: 70 | BG36: =SUM(AU36:BF36) -> 0 | BU36: =SUM(BI36:BT36) -> 0 | CI36: =SUM(BW36:CH36) -> 0 | CW36: =SUM(CK36:CV36) -> 0 | DK36: =SUM(CY36:DJ36) -> 0 | DY36: =SUM(DM36:DX36) -> 0 | EM36: =SUM(EA36:EL36) -> 0
C37: Other | J37: 200 | K37: 200 | L37: 200 | M37: 200 | N37: 200 | O37: 200 | P37: 200 | Q37: =SUM(E37:P37) -> 1400 | S37: 200 | T37: 200 | U37: 200 | V37: 200 | W37: 200 | X37: 200 | Y37: 200 | Z37: 200 | AA37: 200 | AB37: 200 | AC37: 200 | AD37: 200 | AE37: =SUM(S37:AD37) -> 2400 | AG37: 380 | BG37: =SUM(AU37:BF37) -> 0 | BU37: =SUM(BI37:BT37) -> 0 | CI37: =SUM(BW37:CH37) -> 0 | CW37: =SUM(CK37:CV37) -> 0 | DK37: =SUM(CY37:DJ37) -> 0 | DY37: =SUM(DM37:DX37) -> 0 | EM37: =SUM(EA37:EL37) -> 0
C38: Transport | J38: 20 | K38: 20 | L38: 20 | M38: 20 | N38: 20 | O38: 20 | P38: 20 | Q38: =SUM(E38:P38) -> 140 | S38: 50 | T38: 50 | U38: 50 | V38: 50 | W38: 50 | X38: 50 | Y38: 50 | Z38: 50 | AA38: 50 | AB38: 50 | AC38: 50 | AD38: 50 | AE38: =SUM(S38:AD38) -> 600 | AG38: 110 | BG38: =SUM(AU38:BF38) -> 0 | BU38: =SUM(BI38:BT38) -> 0 | CI38: =SUM(BW38:CH38) -> 0 | CW38: =SUM(CK38:CV38) -> 0 | DK38: =SUM(CY38:DJ38) -> 0 | DY38: =SUM(DM38:DX38) -> 0 | EM38: =SUM(EA38:EL38) -> 0
C39: Enter Expenses Category… | Q39: =SUM(E39:P39) -> 0 | AE39: =SUM(S39:AD39) -> 0 | AS39: =SUM(AG39:AR39) -> 0 | BG39: =SUM(AU39:BF39) -> 0 | BU39: =SUM(BI39:BT39) -> 0 | CI39: =SUM(BW39:CH39) -> 0 | CW39: =SUM(CK39:CV39) -> 0 | DK39: =SUM(CY39:DJ39) -> 0 | DY39: =SUM(DM39:DX39) -> 0 | EM39: =SUM(EA39:EL39) -> 0
C40: Enter Expenses Category… | Q40: =SUM(E40:P40) -> 0 | AE40: =SUM(S40:AD40) -> 0 | AS40: =SUM(AG40:AR40) -> 0 | BG40: =SUM(AU40:BF40) -> 0 | BU40: =SUM(BI40:BT40) -> 0 | CI40: =SUM(BW40:CH40) -> 0 | CW40: =SUM(CK40:CV40) -> 0 | DK40: =SUM(CY40:DJ40) -> 0 | DY40: =SUM(DM40:DX40) -> 0 | EM40: =SUM(EA40:EL40) -> 0
C41: Enter Expenses Category… | Q41: =SUM(E41:P41) -> 0 | AE41: =SUM(S41:AD41) -> 0 | AS41: =SUM(AG41:AR41) -> 0 | BG41: =SUM(AU41:BF41) -> 0 | BU41: =SUM(BI41:BT41) -> 0 | CI41: =SUM(BW41:CH41) -> 0 | CW41: =SUM(CK41:CV41) -> 0 | DK41: =SUM(CY41:DJ41) -> 0 | DY41: =SUM(DM41:DX41) -> 0 | EM41: =SUM(EA41:EL41) -> 0
C42: Enter Expenses Category… | Q42: =SUM(E42:P42) -> 0 | AE42: =SUM(S42:AD42) -> 0 | AS42: =SUM(AG42:AR42) -> 0 | BG42: =SUM(AU42:BF42) -> 0 | BU42: =SUM(BI42:BT42) -> 0 | CI42: =SUM(BW42:CH42) -> 0 | CW42: =SUM(CK42:CV42) -> 0 | DK42: =SUM(CY42:DJ42) -> 0 | DY42: =SUM(DM42:DX42) -> 0 | EM42: =SUM(EA42:EL42) -> 0
C43: Enter Expenses Category… | Q43: =SUM(E43:P43) -> 0 | AE43: =SUM(S43:AD43) -> 0 | AS43: =SUM(AG43:AR43) -> 0 | BG43: =SUM(AU43:BF43) -> 0 | BU43: =SUM(BI43:BT43) -> 0 | CI43: =SUM(BW43:CH43) -> 0 | CW43: =SUM(CK43:CV43) -> 0 | DK43: =SUM(CY43:DJ43) -> 0 | DY43: =SUM(DM43:DX43) -> 0 | EM43: =SUM(EA43:EL43) -> 0
C44: Enter Expenses Category… | Q44: =SUM(E44:P44) -> 0 | AE44: =SUM(S44:AD44) -> 0 | AS44: =SUM(AG44:AR44) -> 0 | BG44: =SUM(AU44:BF44) -> 0 | BU44: =SUM(BI44:BT44) -> 0 | CI44: =SUM(BW44:CH44) -> 0 | CW44: =SUM(CK44:CV44) -> 0 | DK44: =SUM(CY44:DJ44) -> 0 | DY44: =SUM(DM44:DX44) -> 0 | EM44: =SUM(EA44:EL44) -> 0
C45: Enter Expenses Category… | Q45: =SUM(E45:P45) -> 0 | AE45: =SUM(S45:AD45) -> 0 | AS45: =SUM(AG45:AR45) -> 0 | BG45: =SUM(AU45:BF45) -> 0 | BU45: =SUM(BI45:BT45) -> 0 | CI45: =SUM(BW45:CH45) -> 0 | CW45: =SUM(CK45:CV45) -> 0 | DK45: =SUM(CY45:DJ45) -> 0 | DY45: =SUM(DM45:DX45) -> 0 | EM45: =SUM(EA45:EL45) -> 0
...

Sheet Budget Tracking
B2: Budget Tracking
C11: Date | D11: Type | E11: Category | F11: Amount | G11: Details | H11: Balance | I11: Effective Date
C12: 45627 | D12: Income | E12: Salary Ivo | F12: 7300 | H12: {=IFERROR(SUMPRODUCT(Tracking[Amount], --(Tracking[Date]<=Tracking[[#This Row],[Date]]), (Tracking[Type]<>"Income") * (-1) + (Tracking[Type]="Income")), "-")} -> 6666 | I12: =IF(AND(Tracking[[#This Row],[Type]]="Income", shift_late_income_status="Active", DAY(Tracking[[#This Row],[Date]])>=shift_late_income_starting_day), DATE(YEAR(Tracking[[#This Row],[Date]]), MONTH(Tracking[[#This Row],[Date]])+1, 1), Tracking[[#This Row],[Date]]) -> 45627
C13: 45627 | D13: Expenses | E13: Baby | F13: 84 | G13: Памперси ДМ | H13: {=IFERROR(SUMPRODUCT(Tracking[Amount], --(Tracking[Date]<=Tracking[[#This Row],[Date]]), (Tracking[Type]<>"Income") * (-1) + (Tracking[Type]="Income")), "-")} -> 6666 | I13: =IF(AND(Tracking[[#This Row],[Type]]="Income", shift_late_income_status="Active", DAY(Tracking[[#This Row],[Date]])>=shift_late_income_starting_day), DATE(YEAR(Tracking[[#This Row],[Date]]), MONTH(Tracking[[#This Row],[Date]])+1, 1), Tracking[[#This Row],[Date]]) -> 45627
C14: 45627 | D14: Expenses | E14: Home improvements | F14: 550 | G14: Амазон кафе машина | H14: {=IFERROR(SUMPRODUCT(Tracking[Amount], --(Tracking[Date]<=Tracking[[#This Row],[Date]]), (Tracking[Type]<>"Income") * (-1) + (Tracking[Type]="Income")), "-")} -> 6666 | I14: =IF(AND(Tracking[[#This Row],[Type]]="Income", shift_late_income_status="Active", DAY(Tracking[[#This Row],[Date]])>=shift_late_income_starting_day), DATE(YEAR(Tracking[[#This Row],[Date]]), MONTH(Tracking[[#This Row],[Date]])+1, 1), Tracking[[#This Row],[Date]]) -> 45627
C15: 45628 | D15: Expenses | E15: Baby | F15: 24 | G15: Капки против колики | H15: {=IFERROR(SUMPRODUCT(Tracking[Amount], --(Tracking[Date]<=Tracking[[#This Row],[Date]]), (Tracking[Type]<>"Income") * (-1) + (Tracking[Type]="Income")), "-")} -> 6481.5 | I15: =IF(AND(Tracking[[#This Row],[Type]]="Income", shift_late_income_status="Active", DAY(Tracking[[#This Row],[Date]])>=shift_late_income_starting_day), DATE(YEAR(Tracking[[#This Row],[Date]]), MONTH(Tracking[[#This Row],[Date]])+1, 1), Tracking[[#This Row],[Date]]) -> 45628
C16: 45628 | D16: Expenses | E16: Clothes | F16: 147 | G16: Манго | H16: {=IFERROR(SUMPRODUCT(Tracking[Amount], --(Tracking[Date]<=Tracking[[#This Row],[Date]]), (Tracking[Type]<>"Income") * (-1) + (Tracking[Type]="Income")), "-")} -> 6481.5 | I16: =IF(AND(Tracking[[#This Row],[Type]]="Income", shift_late_income_status="Active", DAY(Tracking[[#This Row],[Date]])>=shift_late_income_starting_day), DATE(YEAR(Tracking[[#This Row],[Date]]), MONTH(Tracking[[#This Row],[Date]])+1, 1), Tracking[[#This Row],[Date]]) -> 45628
C17: 45628 | D17: Expenses | E17: Subscriptions | F17: 13.5 | G17: Спотифай | H17: {=IFERROR(SUMPRODUCT(Tracking[Amount], --(Tracking[Date]<=Tracking[[#This Row],[Date]]), (Tracking[Type]<>"Income") * (-1) + (Tracking[Type]="Income")), "-")} -> 6481.5 | I17: =IF(AND(Tracking[[#This Row],[Type]]="Income", shift_late_income_status="Active", DAY(Tracking[[#This Row],[Date]])>=shift_late_income_starting_day), DATE(YEAR(Tracking[[#This Row],[Date]]), MONTH(Tracking[[#This Row],[Date]])+1, 1), Tracking[[#This Row],[Date]]) -> 45628
C18: 45629 | D18: Expenses | E18: Eat out | F18: 15 | G18: Табла офис | H18: {=IFERROR(SUMPRODUCT(Tracking[Amount], --(Tracking[Date]<=Tracking[[#This Row],[Date]]), (Tracking[Type]<>"Income") * (-1) + (Tracking[Type]="Income")), "-")} -> 6447.5 | I18: =IF(AND(Tracking[[#This Row],[Type]]="Income", shift_late_income_status="Active", DAY(Tracking[[#This Row],[Date]])>=shift_late_income_starting_day), DATE(YEAR(Tracking[[#This Row],[Date]]), MONTH(Tracking[[#This Row],[Date]])+1, 1), Tracking[[#This Row],[Date]]) -> 45629
C19: 45629 | D19: Expenses | E19: Eat out | F19: 9 | G19: Сандвич АГ | H19: {=IFERROR(SUMPRODUCT(Tracking[Amount], --(Tracking[Date]<=Tracking[[#This Row],[Date]]), (Tracking[Type]<>"Income") * (-1) + (Tracking[Type]="Income")), "-")} -> 6447.5 | I19: =IF(AND(Tracking[[#This Row],[Type]]="Income", shift_late_income_status="Active", DAY(Tracking[[#This Row],[Date]])>=shift_late_income_starting_day), DATE(YEAR(Tracking[[#This Row],[Date]]), MONTH(Tracking[[#This Row],[Date]])+1, 1), Tracking[[#This Row],[Date]]) -> 45629
C20: 45629 | D20: Expenses | E20: Medical | F20: 10 | G20: Женска консултация | H20: {=IFERROR(SUMPRODUCT(Tracking[Amount], --(Tracking[Date]<=Tracking[[#This Row],[Date]]), (Tracking[Type]<>"Income") * (-1) + (Tracking[Type]="Income")), "-")} -> 6447.5 | I20: =IF(AND(Tracking[[#This Row],[Type]]="Income", shift_late_income_status="Active", DAY(Tracking[[#This Row],[Date]])>=shift_late_income_starting_day), DATE(YEAR(Tracking[[#This Row],[Date]]), MONTH(Tracking[[#This Row],[Date]])+1, 1), Tracking[[#This Row],[Date]]) -> 45629
C21: 45630 | D21: Expenses | E21: Eat out | F21: 18 | G21: Time събиране колеги | H21: {=IFERROR(SUMPRODUCT(Tracking[Amount], --(Tracking[Date]<=Tracking[[#This Row],[Date]]), (Tracking[Type]<>"Income") * (-1) + (Tracking[Type]="Income")), "-")} -> 6371.5 | I21: =IF(AND(Tracking[[#This Row],[Type]]="Income", shift_late_income_status="Active", DAY(Tracking[[#This Row],[Date]])>=shift_late_income_starting_day), DATE(YEAR(Tracking[[#This Row],[Date]]), MONTH(Tracking[[#This Row],[Date]])+1, 1), Tracking[[#This Row],[Date]]) -> 45630
C22: 45630 | D22: Expenses | E22: Medical | F22: 51 | G22: Санита | H22: {=IFERROR(SUMPRODUCT(Tracking[Amount], --(Tracking[Date]<=Tracking[[#This Row],[Date]]), (Tracking[Type]<>"Income") * (-1) + (Tracking[Type]="Income")), "-")} -> 6371.5 | I22: =IF(AND(Tracking[[#This Row],[Type]]="Income", shift_late_income_status="Active", DAY(Tracking[[#This Row],[Date]])>=shift_late_income_starting_day), DATE(YEAR(Tracking[[#This Row],[Date]]), MONTH(Tracking[[#This Row],[Date]])+1, 1), Tracking[[#This Row],[Date]]) -> 45630
C23: 45630 | D23: Expenses | E23: Other | F23: 7 | G23: Такси ресторант | H23: {=IFERROR(SUMPRODUCT(Tracking[Amount], --(Tracking[Date]<=Tracking[[#This Row],[Date]]), (Tracking[Type]<>"Income") * (-1) + (Tracking[Type]="Income")), "-")} -> 6371.5 | I23: =IF(AND(Tracking[[#This Row],[Type]]="Income", shift_late_income_status="Active", DAY(Tracking[[#This Row],[Date]])>=shift_late_income_starting_day), DATE(YEAR(Tracking[[#This Row],[Date]]), MONTH(Tracking[[#This Row],[Date]])+1, 1), Tracking[[#This Row],[Date]]) -> 45630
C24: 45631 | D24: Expenses | E24: Eat out | F24: 35 | G24: Нутрио | H24: {=IFERROR(SUMPRODUCT(Tracking[Amount], --(Tracking[Date]<=Tracking[[#This Row],[Date]]), (Tracking[Type]<>"Income") * (-1) + (Tracking[Type]="Income")), "-")} -> 6336.5 | I24: =IF(AND(Tracking[[#This Row],[Type]]="Income", shift_late_income_status="Active", DAY(Tracking[[#This Row],[Date]])>=shift_late_income_starting_day), DATE(YEAR(Tracking[[#This Row],[Date]]), MONTH(Tracking[[#This Row],[Date]])+1, 1), Tracking[[#This Row],[Date]]) -> 45631
... C88: 45651 | D88: Expenses | E88: Transport | F88: 85 | G88: Гориво ЕКО | H88: {=IFERROR(SUMPRODUCT(Tracking[Amount], --(Tracking[Date]<=Tracking[[#This Row],[Date]]), (Tracking[Type]<>"Income") * (-1) + (Tracking[Type]="Income")), "-")} -> 5788.5 | I88: =IF(AND(Tracking[[#This Row],[Type]]="Income", shift_late_income_status="Active", DAY(Tracking[[#This Row],[Date]])>=shift_late_income_starting_day), DATE(YEAR(Tracking[[#This Row],[Date]]), MONTH(Tracking[[#This Row],[Date]])+1, 1), Tracking[[#This Row],[Date]]) -> 45651
C89: 45651 | D89: Savings | E89: Avi Savings | F89: 200 | H89: {=IFERROR(SUMPRODUCT(Tracking[Amount], --(Tracking[Date]<=Tracking[[#This Row],[Date]]), (Tracking[Type]<>"Income") * (-1) + (Tracking[Type]="Income")), "-")} -> 5788.5 | I89: =IF(AND(Tracking[[#This Row],[Type]]="Income", shift_late_income_status="Active", DAY(Tracking[[#This Row],[Date]])>=shift_late_income_starting_day), DATE(YEAR(Tracking[[#This Row],[Date]]), MONTH(Tracking[[#This Row],[Date]])+1, 1), Tracking[[#This Row],[Date]]) -> 45651
C90: 45651 | D90: Income | E90: Other | F90: 4000 | G90: За Ави | H90: {=IFERROR(SUMPRODUCT(Tracking[Amount], --(Tracking[Date]<=Tracking[[#This Row],[Date]]), (Tracking[Type]<>"Income") * (-1) + (Tracking[Type]="Income")), "-")} -> 5788.5 | I90: =IF(AND(Tracking[[#This Row],[Type]]="Income", shift_late_income_status="Active", DAY(Tracking[[#This Row],[Date]])>=shift_late_income_starting_day), DATE(YEAR(Tracking[[#This Row],[Date]]), MONTH(Tracking[[#This Row],[Date]])+1, 1), Tracking[[#This Row],[Date]]) -> 45651
C91: 45651 | D91: Savings | E91: Avi Savings | F91: 4000 | H91: {=IFERROR(SUMPRODUCT(Tracking[Amount], --(Tracking[Date]<=Tracking[[#This Row],[Date]]), (Tracking[Type]<>"Income") * (-1) + (Tracking[Type]="Income")), "-")} -> 5788.5 | I91: =IF(AND(Tracking[[#This Row],[Type]]="Income", shift_late_income_status="Active", DAY(Tracking[[#This Row],[Date]])>=shift_late_income_starting_day), DATE(YEAR(Tracking[[#This Row],[Date]]), MONTH(Tracking[[#This Row],[Date]])+1, 1), Tracking[[#This Row],[Date]]) -> 45651
C92: 45651 | D92: Savings | E92: Metlife | F92: 686 | H92: {=IFERROR(SUMPRODUCT(Tracking[Amount], --(Tracking[Date]<=Tracking[[#This Row],[Date]]), (Tracking[Type]<>"Income") * (-1) + (Tracking[Type]="Income")), "-")} -> 5788.5 | I92: =IF(AND(Tracking[[#This Row],[Type]]="Income", shift_late_income_status="Active", DAY(Tracking[[#This Row],[Date]])>=shift_late_income_starting_day), DATE(YEAR(Tracking[[#This Row],[Date]]), MONTH(Tracking[[#This Row],[Date]])+1, 1), Tracking[[#This Row],[Date]]) -> 45651
C93: 45652 | D93: Expenses | E93: Subscriptions | F93: 16 | G93: Револют Премиум | H93: {=IFERROR(SUMPRODUCT(Tracking[Amount], --(Tracking[Date]<=Tracking[[#This Row],[Date]]), (Tracking[Type]<>"Income") * (-1) + (Tracking[Type]="Income")), "-")} -> 5665.5 | I93: =IF(AND(Tracking[[#This Row],[Type]]="Income", shift_late_income_status="Active", DAY(Tracking[[#This Row],[Date]])>=shift_late_income_starting_day), DATE(YEAR(Tracking[[#This Row],[Date]]), MONTH(Tracking[[#This Row],[Date]])+1, 1), Tracking[[#This Row],[Date]]) -> 45652
C94: 45652 | D94: Expenses | E94: Groceries | F94: 7 | G94: Кафе | H94: {=IFERROR(SUMPRODUCT(Tracking[Amount], --(Tracking[Date]<=Tracking[[#This Row],[Date]]), (Tracking[Type]<>"Income") * (-1) + (Tracking[Type]="Income")), "-")} -> 5665.5 | I94: =IF(AND(Tracking[[#This Row],[Type]]="Income", shift_late_income_status="Active", DAY(Tracking[[#This Row],[Date]])>=shift_late_income_starting_day), DATE(YEAR(Tracking[[#This Row],[Date]]), MONTH(Tracking[[#This Row],[Date]])+1, 1), Tracking[[#This Row],[Date]]) -> 45652
C95: 45652 | D95: Expenses | E95: Other | F95: 100 | G95: Кико РД | H95: {=IFERROR(SUMPRODUCT(Tracking[Amount], --(Tracking[Date]<=Tracking[[#This Row],[Date]]), (Tracking[Type]<>"Income") * (-1) + (Tracking[Type]="Income")), "-")} -> 5665.5 | I95: =IF(AND(Tracking[[#This Row],[Type]]="Income", shift_late_income_status="Active", DAY(Tracking[[#This Row],[Date]])>=shift_late_income_starting_day), DATE(YEAR(Tracking[[#This Row],[Date]]), MONTH(Tracking[[#This Row],[Date]])+1, 1), Tracking[[#This Row],[Date]]) -> 45652
C96: 45653 | D96: Expenses | E96: Mortgage | F96: 1260 | H96: {=IFERROR(SUMPRODUCT(Tracking[Amount], --(Tracking[Date]<=Tracking[[#This Row],[Date]]), (Tracking[Type]<>"Income") * (-1) + (Tracking[Type]="Income")), "-")} -> 1962.5 | I96: =IF(AND(Tracking[[#This Row],[Type]]="Income", shift_late_income_status="Active", DAY(Tracking[[#This Row],[Date]])>=shift_late_income_starting_day), DATE(YEAR(Tracking[[#This Row],[Date]]), MONTH(Tracking[[#This Row],[Date]])+1, 1), Tracking[[#This Row],[Date]]) -> 45653
C97: 45653 | D97: Expenses | E97: Mortgage | F97: 1960 | H97: {=IFERROR(SUMPRODUCT(Tracking[Amount], --(Tracking[Date]<=Tracking[[#This Row],[Date]]), (Tracking[Type]<>"Income") * (-1) + (Tracking[Type]="Income")), "-")} -> 1962.5 | I97: =IF(AND(Tracking[[#This Row],[Type]]="Income", shift_late_income_status="Active", DAY(Tracking[[#This Row],[Date]])>=shift_late_income_starting_day), DATE(YEAR(Tracking[[#This Row],[Date]]), MONTH(Tracking[[#This Row],[Date]])+1, 1), Tracking[[#This Row],[Date]]) -> 45653
